#VRML_SIM R2019a utf8
WorldInfo {
  contactProperties [
    ContactProperties {
      material1 ""
      material2 ""
      coulombFriction [
        0
      ]
    }
  ]
}
Viewpoint {
  orientation -0.6219024822879966 0.7593455897795578 0.1913937768224547 0.7369332235424505
  position 1.3107793588669212 1.4111856298881487 1.5945453840445385
}
TexturedBackground {
}
TexturedBackgroundLight {
}
Floor {
}
Solid {
  translation 0.6000000000000003 0.13999999999999996 0.2900000000000001
  children [
    Shape {
      appearance PBRAppearance {
        baseColor 0.1803921568627451 0.20392156862745098 0.21176470588235294
      }
      geometry DEF OBS_1 Box {
        size 0.1 0.25 0.1
      }
    }
  ]
  name "solid(5)"
  boundingObject USE OBS_1
}
Solid {
  translation -0.25 0.13999999999999996 0.009999999999999969
  children [
    Shape {
      appearance PBRAppearance {
        baseColor 0.1803921568627451 0.20392156862745098 0.21176470588235294
      }
      geometry DEF OBS_1 Box {
        size 0.1 0.25 0.1
      }
    }
  ]
  name "solid(4)"
  boundingObject USE OBS_1
}
Solid {
  translation 0.06000000000000018 0.13999999999999996 0.5
  children [
    Shape {
      appearance PBRAppearance {
        baseColor 0.1803921568627451 0.20392156862745098 0.21176470588235294
      }
      geometry DEF OBS_1 Box {
        size 0.1 0.25 0.1
      }
    }
  ]
  name "solid(3)"
  boundingObject USE OBS_1
}
Solid {
  translation 0.3900000000000001 0.13999999999999996 -0.37000000000000033
  children [
    Shape {
      appearance PBRAppearance {
        baseColor 0.1803921568627451 0.20392156862745098 0.21176470588235294
      }
      geometry DEF OBS_1 Box {
        size 0.1 0.25 0.1
      }
    }
  ]
  name "solid(2)"
  boundingObject USE OBS_1
}
Robot {
  translation 0 0.07999999999999997 0
  children [
    DEF GR_BODY Group {
      children [
        DEF ROBOT_BODY Shape {
          appearance PBRAppearance {
            baseColor 0.9372549019607843 0.1607843137254902 0.1607843137254902
          }
          geometry DEF G_BODY Box {
            size 0.25 0.07 0.1
          }
        }
        Transform {
          translation 0.11 -0.05 0
          children [
            Shape {
              appearance PBRAppearance {
                roughness 1
                metalness 0
              }
              geometry Sphere {
                radius 0.015
              }
            }
          ]
        }
      ]
    }
    DEF WHEEL1_JOINT HingeJoint {
      jointParameters HingeJointParameters {
        axis 0 0 1
        anchor -0.05 0 0.06
      }
      device [
        PositionSensor {
          name "encoder1"
        }
        RotationalMotor {
          name "motor_right"
          maxVelocity 6.66
        }
      ]
      endPoint DEF WHEEL1 Solid {
        translation -0.05 0 0.06
        rotation -1 0 0 1.57
        children [
          DEF SH_WHEEL Shape {
            appearance PBRAppearance {
              baseColor 0 0 0
              roughness 1
              metalness 0
            }
            geometry DEF G_WHEEL Cylinder {
              height 0.02
              radius 0.075
            }
          }
        ]
        boundingObject USE G_WHEEL
        physics Physics {
        }
      }
    }
    DEF WHEEL2_JOINT HingeJoint {
      jointParameters HingeJointParameters {
        axis 0 0 1
        anchor -0.05 0 -0.06
      }
      device [
        PositionSensor {
          name "encoder2"
        }
        RotationalMotor {
          name "motor_left"
          maxVelocity 6.66
        }
      ]
      endPoint Solid {
        translation -0.05 0 -0.06
        rotation -1 0 0 1.57
        children [
          DEF WH_SHAPE2 Shape {
            appearance PBRAppearance {
              baseColor 0 0 0
              roughness 1
              metalness 0
            }
            geometry Cylinder {
              height 0.02
              radius 0.075
            }
          }
        ]
        name "solid(1)"
        boundingObject USE WH_SHAPE2
        physics Physics {
        }
      }
    }
    DistanceSensor {
      translation 0.125 0 0
      children [
        Shape {
          appearance PBRAppearance {
            baseColor 0.1803921568627451 0.20392156862745098 0.21176470588235294
          }
          geometry Box {
            size 0.02 0.01 0.01
          }
        }
      ]
      name "distance_sensor"
      lookupTable [
        0 0 0
        0.05 0 0
        2 1066 0
      ]
      resolution 1
    }
  ]
  boundingObject USE GR_BODY
  physics Physics {
  }
  controller "robot1"
}
Solid {
  translation 0.6000000000000003 0.13999999999999996 0
  children [
    Shape {
      appearance PBRAppearance {
        baseColor 0.1803921568627451 0.20392156862745098 0.21176470588235294
      }
      geometry DEF OBS_1 Box {
        size 0.1 0.25 0.1
      }
    }
  ]
  boundingObject USE OBS_1
}
Solid {
  translation -0.2400000000000003 0.13999999999999996 -0.27
  children [
    Shape {
      appearance PBRAppearance {
        baseColor 0.1803921568627451 0.20392156862745098 0.21176470588235294
      }
      geometry DEF OBS_1 Box {
        size 0.1 0.25 0.1
      }
    }
  ]
  name "solid(1)"
  boundingObject USE OBS_1
}
