#VRML_SIM R2019a utf8
WorldInfo {
}
Viewpoint {
  orientation -0.3121274402376908 -0.9422739759469607 -0.12122794770090463 0.8294508121797022
  position -0.4192948377333777 0.1959309544791331 0.41424459899059696
}
TexturedBackground {
}
TexturedBackgroundLight {
}
Floor {
}
Robot {
  translation 0 0.09 0
  children [
    DEF ROBOR_BODY Shape {
      appearance PBRAppearance {
        baseColor 0.9372549019607843 0.1607843137254902 0.1607843137254902
      }
      geometry DEF G_BODY Box {
        size 0.25 0.07 0.1
      }
    }
    DEF WHEEL1_JOINT HingeJoint {
      jointParameters HingeJointParameters {
        axis 0 0 1
        anchor -0.05 0 0.06
      }
      device [
        RotationalMotor {
          name "motor_right"
        }
      ]
      endPoint DEF WHEEL1 Solid {
        translation -0.05 0 0.06
        rotation 1 0 0 1.57
        children [
          Shape {
            appearance PBRAppearance {
              baseColor 0 0 0
              roughness 1
              metalness 0
            }
            geometry DEF G_WHEEL Cylinder {
              height 0.02
              radius 0.075
            }
          }
        ]
        boundingObject USE G_WHEEL
        physics Physics {
        }
      }
    }
  ]
  boundingObject USE G_BODY
  physics Physics {
  }
}
