#VRML_SIM R2019a utf8
WorldInfo {
}
Viewpoint {
  orientation -0.29063578376992977 -0.9495752229954739 -0.11763391120563195 0.8548180002760211
  position -0.4313397037069437 0.1911392472450654 0.40594235034213744
}
TexturedBackground {
}
TexturedBackgroundLight {
}
Floor {
}
Robot {
  translation 0 0.09 0
  children [
    DEF ROBOR_BODY Shape {
      appearance PBRAppearance {
        baseColor 0.9372549019607843 0.1607843137254902 0.1607843137254902
      }
      geometry DEF G_BODY Box {
        size 0.25 0.07 0.1
      }
    }
    DEF WHEEL1_JOINT HingeJoint {
      jointParameters HingeJointParameters {
        axis 0 0 1
        anchor -0.05 0 0.06
      }
      device [
        RotationalMotor {
          name "robot_motor_right"
        }
      ]
      endPoint DEF WHEEL1 Solid {
        translation -0.05 0 0.06
        rotation 1 0 0 1.57
        children [
          Shape {
            appearance PBRAppearance {
              baseColor 0 0 0
              roughness 1
              metalness 0
            }
            geometry DEF G_WHEEL Cylinder {
              height 0.02
              radius 0.075
            }
          }
        ]
        boundingObject USE G_WHEEL
      }
    }
  ]
  boundingObject USE G_BODY
  physics Physics {
  }
}
