#VRML_SIM R2019a utf8
WorldInfo {
}
Viewpoint {
  orientation -0.6034083939307864 -0.764721865919107 -0.2260503880091082 0.9372802586475144
  position -0.9732140278246129 0.7925887871755368 0.9596052790777638
}
TexturedBackground {
}
TexturedBackgroundLight {
}
Floor {
}
Robot {
  translation 0 0.07999999999999997 0
  children [
    DEF GR_BODY Group {
      children [
        DEF ROBOT_BODY Shape {
          appearance PBRAppearance {
            baseColor 0.9372549019607843 0.1607843137254902 0.1607843137254902
          }
          geometry DEF G_BODY Box {
            size 0.25 0.07 0.1
          }
        }
        Transform {
          translation 0.11 -0.05 0
          children [
            Shape {
              appearance PBRAppearance {
                roughness 1
                metalness 0
              }
              geometry Sphere {
                radius 0.015
              }
            }
          ]
        }
      ]
    }
    DEF WHEEL1_JOINT HingeJoint {
      jointParameters HingeJointParameters {
        axis 0 0 1
        anchor -0.05 0 0.06
      }
      device [
        RotationalMotor {
          name "motor_right"
        }
      ]
      endPoint DEF WHEEL1 Solid {
        translation -0.05 0 0.06
        rotation 1 0 0 -1.57
        children [
          DEF SH_WHEEL Shape {
            appearance PBRAppearance {
              baseColor 0 0 0
              roughness 1
              metalness 0
            }
            geometry DEF G_WHEEL Cylinder {
              height 0.02
              radius 0.075
            }
          }
        ]
        boundingObject USE G_WHEEL
        physics Physics {
        }
      }
    }
    DEF WHEEL2_JOINT HingeJoint {
      jointParameters HingeJointParameters {
        axis 0 0 1
        anchor -0.05 0 -0.06
      }
      device [
        RotationalMotor {
          name "motor_left"
        }
      ]
      endPoint Solid {
        translation -0.05 0 -0.06
        rotation -1 0 0 1.57
        children [
          DEF WH_SHAPE2 Shape {
            appearance PBRAppearance {
              baseColor 0 0 0
              roughness 1
              metalness 0
            }
            geometry Cylinder {
              height 0.02
              radius 0.075
            }
          }
        ]
        name "solid(1)"
        boundingObject USE WH_SHAPE2
        physics Physics {
        }
      }
    }
  ]
  boundingObject USE GR_BODY
  physics Physics {
  }
  controller "robot1"
}
