#VRML_SIM R2019a utf8
WorldInfo {
}
Viewpoint {
  orientation -0.7816887610559997 0.606453251649978 0.14552365581548815 0.550496171652073
  position 1.2086716026627693 1.0353640749557682 2.1171721451256964
}
TexturedBackground {
}
TexturedBackgroundLight {
}
Floor {
}
Robot {
  translation 0 0.07999999999999997 0
  children [
    DEF GR_BODY Group {
      children [
        DEF ROBOT_BODY Shape {
          appearance PBRAppearance {
            baseColor 0.9372549019607843 0.1607843137254902 0.1607843137254902
          }
          geometry DEF G_BODY Box {
            size 0.25 0.07 0.1
          }
        }
        Transform {
          translation 0.11 -0.05 0
          children [
            Shape {
              appearance PBRAppearance {
                roughness 1
                metalness 0
              }
              geometry Sphere {
                radius 0.015
              }
            }
          ]
        }
      ]
    }
    DEF WHEEL1_JOINT HingeJoint {
      jointParameters HingeJointParameters {
        axis 0 0 1
        anchor -0.05 0 0.06
      }
      device [
        PositionSensor {
          name "encoder1"
        }
        RotationalMotor {
          name "motor_right"
          maxVelocity 6.66
        }
      ]
      endPoint DEF WHEEL1 Solid {
        translation -0.05 0 0.06
        rotation -1 0 0 1.57
        children [
          DEF SH_WHEEL Shape {
            appearance PBRAppearance {
              baseColor 0 0 0
              roughness 1
              metalness 0
            }
            geometry DEF G_WHEEL Cylinder {
              height 0.02
              radius 0.075
            }
          }
        ]
        boundingObject USE G_WHEEL
        physics Physics {
        }
      }
    }
    DEF WHEEL2_JOINT HingeJoint {
      jointParameters HingeJointParameters {
        axis 0 0 1
        anchor -0.05 0 -0.06
      }
      device [
        PositionSensor {
          name "encoder2"
        }
        RotationalMotor {
          name "motor_left"
          maxVelocity 6.66
        }
      ]
      endPoint Solid {
        translation -0.05 0 -0.06
        rotation -1 0 0 1.57
        children [
          DEF WH_SHAPE2 Shape {
            appearance PBRAppearance {
              baseColor 0 0 0
              roughness 1
              metalness 0
            }
            geometry Cylinder {
              height 0.02
              radius 0.075
            }
          }
        ]
        name "solid(1)"
        boundingObject USE WH_SHAPE2
        physics Physics {
        }
      }
    }
    DistanceSensor {
      translation 0.125 0 0
      children [
        Shape {
          appearance PBRAppearance {
            baseColor 0.1803921568627451 0.20392156862745098 0.21176470588235294
          }
          geometry Box {
            size 0.02 0.01 0.01
          }
        }
      ]
      name "distance_sensor"
      lookupTable [
        0 0 0
        0.05 0 0
        2 1023 0
      ]
      resolution 1
    }
  ]
  boundingObject USE GR_BODY
  physics Physics {
    mass 10
  }
  controller "robot1"
}
Solid {
  translation 0.6000000000000003 0.13999999999999996 0
  children [
    Shape {
      appearance PBRAppearance {
        baseColor 0.1803921568627451 0.20392156862745098 0.21176470588235294
      }
      geometry DEF OBS_1 Box {
        size 0.1 0.25 0.1
      }
    }
  ]
  boundingObject USE OBS_1
}
