#VRML_SIM R2019a utf8
WorldInfo {
}
Viewpoint {
  orientation -0.6321321448968461 -0.7028637693414125 -0.32617705795364366 1.284976867317138
  position -0.3764090328564821 0.47492399048316697 0.2724191677313937
}
TexturedBackground {
}
TexturedBackgroundLight {
}
Floor {
}
Robot {
  translation 0 0.1 0
  children [
    DEF ROBOR_BODY Shape {
      appearance PBRAppearance {
        baseColor 0.9372549019607843 0.1607843137254902 0.1607843137254902
      }
      geometry DEF G_BODY Box {
        size 0.25 0.07 0.1
      }
    }
    DEF WHEEL1_JOINT HingeJoint {
      jointParameters HingeJointParameters {
        axis 0 0 1
        anchor -0.05 0 0.06
      }
      device [
        RotationalMotor {
          name "motor_right"
        }
      ]
      endPoint DEF WHEEL1 Solid {
        translation -0.05 0 0.06
        rotation 1 0 0 1.57
        children [
          DEF SH_WHEEL Shape {
            appearance PBRAppearance {
              baseColor 0 0 0
              roughness 1
              metalness 0
            }
            geometry DEF G_WHEEL Cylinder {
              height 0.02
              radius 0.075
            }
          }
        ]
        boundingObject USE G_WHEEL
        physics Physics {
        }
      }
    }
    DEF WHEEL2_JOINT HingeJoint {
      jointParameters HingeJointParameters {
        axis 0 0 1
        anchor -0.05 0 -0.06
      }
      device [
        RotationalMotor {
          name "motor_left"
        }
      ]
      endPoint Solid {
        translation -0.05 0 -0.06
        rotation 1 0 0 1.57
        children [
          USE SH_WHEEL
        ]
        name "solid(1)"
        boundingObject USE SH_WHEEL
        physics Physics {
        }
      }
    }
  ]
  boundingObject USE G_BODY
  physics Physics {
  }
  controller "robot1"
}
